[2024-08-28T02:02:32.936+0000] {taskinstance.py:1165} INFO - Dependencies all met for <TaskInstance: xcom_dag.t2 scheduled__2024-08-27T00:00:00+00:00 [queued]>
[2024-08-28T02:02:32.946+0000] {taskinstance.py:1165} INFO - Dependencies all met for <TaskInstance: xcom_dag.t2 scheduled__2024-08-27T00:00:00+00:00 [queued]>
[2024-08-28T02:02:32.946+0000] {taskinstance.py:1362} INFO - 
--------------------------------------------------------------------------------
[2024-08-28T02:02:32.946+0000] {taskinstance.py:1363} INFO - Starting attempt 1 of 1
[2024-08-28T02:02:32.946+0000] {taskinstance.py:1364} INFO - 
--------------------------------------------------------------------------------
[2024-08-28T02:02:32.962+0000] {taskinstance.py:1383} INFO - Executing <Task(PythonOperator): t2> on 2024-08-27 00:00:00+00:00
[2024-08-28T02:02:32.970+0000] {standard_task_runner.py:55} INFO - Started process 1947 to run task
[2024-08-28T02:02:32.973+0000] {standard_task_runner.py:82} INFO - Running: ['***', 'tasks', 'run', 'xcom_dag', 't2', 'scheduled__2024-08-27T00:00:00+00:00', '--job-id', '122', '--raw', '--subdir', 'DAGS_FOLDER/course_xcom_dag.py', '--cfg-path', '/tmp/tmpulbp8bj_']
[2024-08-28T02:02:32.974+0000] {standard_task_runner.py:83} INFO - Job 122: Subtask t2
[2024-08-28T02:02:33.036+0000] {task_command.py:376} INFO - Running <TaskInstance: xcom_dag.t2 scheduled__2024-08-27T00:00:00+00:00 [running]> on host 1542d298b92a
[2024-08-28T02:02:33.111+0000] {taskinstance.py:1592} INFO - Exporting the following env vars:
AIRFLOW_CTX_DAG_OWNER=***
AIRFLOW_CTX_DAG_ID=xcom_dag
AIRFLOW_CTX_TASK_ID=t2
AIRFLOW_CTX_EXECUTION_DATE=2024-08-27T00:00:00+00:00
AIRFLOW_CTX_TRY_NUMBER=1
AIRFLOW_CTX_DAG_RUN_ID=scheduled__2024-08-27T00:00:00+00:00
[2024-08-28T02:02:33.112+0000] {taskinstance.py:1851} ERROR - Task failed with exception
Traceback (most recent call last):
  File "/home/airflow/.local/lib/python3.7/site-packages/airflow/operators/python.py", line 175, in execute
    return_value = self.execute_callable()
  File "/home/airflow/.local/lib/python3.7/site-packages/airflow/operators/python.py", line 193, in execute_callable
    return self.python_callable(*self.op_args, **self.op_kwargs)
  File "/opt/airflow/dags/course_xcom_dag.py", line 13, in _t2
    task_instance.push(key="task_2_xcom", value=200)
AttributeError: 'TaskInstance' object has no attribute 'push'
[2024-08-28T02:02:33.120+0000] {taskinstance.py:1406} INFO - Marking task as FAILED. dag_id=xcom_dag, task_id=t2, execution_date=20240827T000000, start_date=20240828T020232, end_date=20240828T020233
[2024-08-28T02:02:33.132+0000] {standard_task_runner.py:105} ERROR - Failed to execute job 122 for task t2 ('TaskInstance' object has no attribute 'push'; 1947)
[2024-08-28T02:02:33.144+0000] {local_task_job.py:164} INFO - Task exited with return code 1
[2024-08-28T02:02:33.175+0000] {local_task_job.py:273} INFO - 0 downstream tasks scheduled from follow-on schedule check
