[2024-08-28T22:09:24.267+0000] {taskinstance.py:1165} INFO - Dependencies all met for <TaskInstance: elastic_dag.print_es_info scheduled__2024-08-27T00:00:00+00:00 [queued]>
[2024-08-28T22:09:24.276+0000] {taskinstance.py:1165} INFO - Dependencies all met for <TaskInstance: elastic_dag.print_es_info scheduled__2024-08-27T00:00:00+00:00 [queued]>
[2024-08-28T22:09:24.276+0000] {taskinstance.py:1362} INFO - 
--------------------------------------------------------------------------------
[2024-08-28T22:09:24.276+0000] {taskinstance.py:1363} INFO - Starting attempt 1 of 1
[2024-08-28T22:09:24.276+0000] {taskinstance.py:1364} INFO - 
--------------------------------------------------------------------------------
[2024-08-28T22:09:24.289+0000] {taskinstance.py:1383} INFO - Executing <Task(PythonOperator): print_es_info> on 2024-08-27 00:00:00+00:00
[2024-08-28T22:09:24.299+0000] {standard_task_runner.py:55} INFO - Started process 400 to run task
[2024-08-28T22:09:24.302+0000] {standard_task_runner.py:82} INFO - Running: ['***', 'tasks', 'run', 'elastic_dag', 'print_es_info', 'scheduled__2024-08-27T00:00:00+00:00', '--job-id', '152', '--raw', '--subdir', 'DAGS_FOLDER/course_elastic_dag.py', '--cfg-path', '/tmp/tmpixh433zi']
[2024-08-28T22:09:24.304+0000] {standard_task_runner.py:83} INFO - Job 152: Subtask print_es_info
[2024-08-28T22:09:24.366+0000] {task_command.py:376} INFO - Running <TaskInstance: elastic_dag.print_es_info scheduled__2024-08-27T00:00:00+00:00 [running]> on host 15e03dfad604
[2024-08-28T22:09:24.440+0000] {taskinstance.py:1592} INFO - Exporting the following env vars:
AIRFLOW_CTX_DAG_OWNER=***
AIRFLOW_CTX_DAG_ID=elastic_dag
AIRFLOW_CTX_TASK_ID=print_es_info
AIRFLOW_CTX_EXECUTION_DATE=2024-08-27T00:00:00+00:00
AIRFLOW_CTX_TRY_NUMBER=1
AIRFLOW_CTX_DAG_RUN_ID=scheduled__2024-08-27T00:00:00+00:00
[2024-08-28T22:09:24.441+0000] {taskinstance.py:1851} ERROR - Task failed with exception
Traceback (most recent call last):
  File "/home/airflow/.local/lib/python3.7/site-packages/airflow/operators/python.py", line 175, in execute
    return_value = self.execute_callable()
  File "/home/airflow/.local/lib/python3.7/site-packages/airflow/operators/python.py", line 193, in execute_callable
    return self.python_callable(*self.op_args, **self.op_kwargs)
  File "/opt/airflow/dags/course_elastic_dag.py", line 8, in _print_es_info
    hook = ElasticHook()
  File "/opt/airflow/plugins/hooks/elastic/elastic_hook.py", line 8, in __init__
    super().__init__(args, kwargs)
TypeError: __init__() takes from 1 to 2 positional arguments but 3 were given
[2024-08-28T22:09:24.449+0000] {taskinstance.py:1406} INFO - Marking task as FAILED. dag_id=elastic_dag, task_id=print_es_info, execution_date=20240827T000000, start_date=20240828T220924, end_date=20240828T220924
[2024-08-28T22:09:24.460+0000] {standard_task_runner.py:105} ERROR - Failed to execute job 152 for task print_es_info (__init__() takes from 1 to 2 positional arguments but 3 were given; 400)
[2024-08-28T22:09:24.473+0000] {local_task_job.py:164} INFO - Task exited with return code 1
[2024-08-28T22:09:24.493+0000] {local_task_job.py:273} INFO - 0 downstream tasks scheduled from follow-on schedule check
